Workbook

Sheet Responses
A1: Submitted at | B1: Form language | C1: Email | D1: Student first name | E1: Student last name | F1: Preferred name | G1: Student date of birth | H1: Grade level | I1: School | J1: School district | K1: ZIP code | L1: Student email | M1: Student phone | N1: Parent/guardian name | O1: Relationship to student | P1: Parent/guardian email | Q1: Parent/guardian phone | R1: Preferred contact method | S1: Household size | T1: Parent/guardian education | U1: First-generation college | V1: School lunch | W1: English learner | X1: Race/ethnicity | Y1: Barriers to participation | Z1: Household income range | AA1: Programs of interest | AB1: Student goals | AC1: Plan after high school | AD1: GPA | AE1: Academic performance | AF1: Academic support needed | AG1: Goal for this year | AH1: Wants virtual tutoring | AI1: Tutoring subjects | AJ1: Tutoring time | AK1: Parent engagement interest | AL1: Parent session times | AM1: Parent topics | AN1: Emergency contact name | AO1: Emergency contact relationship | AP1: Emergency contact phone | AQ1: Accessibility needs | AR1: How they heard about us | AS1: Participation consent | AT1: Evaluation consent | AU1: Photo/video release | AV1: Signature | AW1: Signature date

Sheet Summary
A1: Aspire High — Applications 2026–2027
A2: Every figure below is a formula over the Responses tab and updates as applications arrive. Nothing on this tab needs typing.
A4: Applications | B4: Count | C4: % of total | D4: Note
A5: Total applications | B5: =MAX(0,COUNTA(Responses!A:A)-1) -> 0
A6: Submitted on the English form | B6: =COUNTIF(Responses!B:B,"English") -> 0 | C6: =IF($B$5=0,0,B6/$B$5) -> 0
A7: Submitted on the Spanish form | B7: =COUNTIF(Responses!B:B,"Spanish") -> 0 | C7: =IF($B$5=0,0,B7/$B$5) -> 0
A8: Grade (counts entries containing the number)
A9: Grade 9 | B9: =COUNTIF(Responses!H:H,"*9*") -> 0 | C9: =IF($B$5=0,0,B9/$B$5) -> 0 | D9: Grade is typed freely on the form, so an entry written as a word — "Freshman" — is not counted here.
A10: Grade 10 | B10: =COUNTIF(Responses!H:H,"*10*") -> 0 | C10: =IF($B$5=0,0,B10/$B$5) -> 0
A11: Grade 11 | B11: =COUNTIF(Responses!H:H,"*11*") -> 0 | C11: =IF($B$5=0,0,B11/$B$5) -> 0
A12: Grade 12 | B12: =COUNTIF(Responses!H:H,"*12*") -> 0 | C12: =IF($B$5=0,0,B12/$B$5) -> 0
A13: Grant reporting
A14: First-generation college students | B14: =COUNTIF(Responses!U:U,"Yes") -> 0 | C14: =IF($B$5=0,0,B14/$B$5) -> 0
A15: Free or reduced-price lunch | B15: =COUNTIF(Responses!V:V,"Free lunch")+COUNTIF(Responses!V:V,"Reduced-price lunch") -> 0 | C15: =IF($B$5=0,0,B15/$B$5) -> 0 | D15: A common proxy for household income in grant applications.
A16: English or multilingual learners | B16: =COUNTIF(Responses!W:W,"Yes") -> 0 | C16: =IF($B$5=0,0,B16/$B$5) -> 0
A17: Hispanic or Latino | B17: =COUNTIF(Responses!X:X,"*Hispanic or Latino*") -> 0 | C17: =IF($B$5=0,0,B17/$B$5) -> 0 | D17: Race/ethnicity is select-all-that-apply, so these rows can add up to more than the total.
A18: Black or African American | B18: =COUNTIF(Responses!X:X,"*Black or African American*") -> 0 | C18: =IF($B$5=0,0,B18/$B$5) -> 0
A19: White | B19: =COUNTIF(Responses!X:X,"*White*") -> 0 | C19: =IF($B$5=0,0,B19/$B$5) -> 0
A20: Asian | B20: =COUNTIF(Responses!X:X,"*Asian*") -> 0 | C20: =IF($B$5=0,0,B20/$B$5) -> 0
A21: Two or more races | B21: =COUNTIF(Responses!X:X,"*Two or more races*") -> 0 | C21: =IF($B$5=0,0,B21/$B$5) -> 0
A22: Programme interest
A23: Want free virtual tutoring | B23: =COUNTIF(Responses!AH:AH,"Yes") -> 0 | C23: =IF($B$5=0,0,B23/$B$5) -> 0
A24: Want parent engagement sessions | B24: =COUNTIF(Responses!AK:AK,"Yes") -> 0 | C24: =IF($B$5=0,0,B24/$B$5) -> 0
A25: Check before every session
A26: Photo/video NOT authorised | B26: =COUNTIF(Responses!AU:AU,"No") -> 0 | C26: =IF($B$5=0,0,B26/$B$5) -> 0 | D26: Filter the Responses tab on Photo/video release = No before any photo or video is taken or posted.
A27: Participation consent NOT given | B27: =COUNTIF(Responses!AS:AS,"I do not agree") -> 0 | C27: =IF($B$5=0,0,B27/$B$5) -> 0 | D27: These students cannot take part until consent is given.

Sheet Field guide
A1: How to use this workbook
A2: • Responses — one row per application, added automatically by the website. Do not type in it or sort it in place; filter instead.
A3: • You may add your own columns to the RIGHT of the last heading (for example Status, Contacted by). The script leaves them alone.
A4: • Summary — live counts for grant reporting. Nothing there needs typing.
A5: • Row 1 of Responses is matched by heading text: renaming a heading starts a new column instead of filling the old one.
A6: • Keep the spreadsheet's sharing on Restricted. It holds children's personal details.
A7: • The Example answer column below shows one made-up application, for format only. It is not a real family.
A9: Column | B9: Heading in Responses | C9: Question on the form | D9: Required | E9: Answer type | F9: Example answer (made up) | G9: Note
A10: A | B10: Submitted at | C10: Added automatically | E10: Date and time | F10: 2026-10-02 18:41 | G10: Added by the script at the moment of submission, New York time.
A11: B | B11: Form language | C11: Hidden — which page was used | E11: Text | F11: Spanish | G11: English or Spanish — which page the family used. Answers themselves are always stored in English.
A12: C | B12: Email | C12: Email | D12: Yes | E12: Text | F12: maria.lopez@example.org
A13: D | B13: Student first name | C13: Student First Name | D13: Yes | E13: Text | F13: Ana
A14: E | B14: Student last name | C14: Student Last Name | D14: Yes | E14: Text | F14: Lopez
A15: F | B15: Preferred name | C15: Preferred Name | E15: Text
A16: G | B16: Student date of birth | C16: Student Date of Birth | D16: Yes | E16: Date | F16: 2011-04-02
A17: H | B17: Grade level | C17: Current Grade Level | D17: Yes | E17: Text | F17: 9
A18: I | B18: School | C18: School Name | D18: Yes | E18: Text | F18: Franklin High School
A19: J | B19: School district | C19: School District | E19: Text
A20: K | B20: ZIP code | C20: ZIP Code | D20: Yes | E20: Text | F20: 08724 | G20: Stored as text so the leading zero of New Jersey ZIP codes is kept.
A21: L | B21: Student email | C21: Student Email Address | E21: Text
A22: M | B22: Student phone | C22: Student Phone Number | E22: Text
A23: N | B23: Parent/guardian name | C23: Parent/Guardian Full Name | D23: Yes | E23: Text | F23: Maria Lopez
A24: O | B24: Relationship to student | C24: Relationship to Student | D24: Yes | E24: Text | F24: Mother
A25: P | B25: Parent/guardian email | C25: Parent/Guardian Email | D25: Yes | E25: Text | F25: maria.lopez@example.org
A26: Q | B26: Parent/guardian phone | C26: Parent/Guardian Phone Number | D26: Yes | E26: Text | F26: +1 732 555 0100
A27: R | B27: Preferred contact method | C27: Preferred Contact Method | D27: Yes | E27: Choose one | F27: Text Message
A28: S | B28: Household size | C28: Household Size | D28: Yes | E28: Text | F28: 4
A29: T | B29: Parent/guardian education | C29: Highest Level of Education Completed by Parent/Guardian | D29: Yes | E29: Text | F29: High school diploma
A30: U | B30: First-generation college | C30: Would the student be the first person in their immediate family to attend college? | D30: Yes | E30: Choose one | F30: Yes
A31: V | B31: School lunch | C31: Does the student receive free, reduced-price, or full-paid school lunch? | D31: Yes | E31: Choose one | F31: Free lunch
A32: W | B32: English learner | C32: Is the student an English Learner or multilingual learner? | D32: Yes | E32: Choose one | F32: No
A33: X | B33: Race/ethnicity | C33: Race/Ethnicity | D33: Yes | E33: Choose several | F33: Hispanic or Latino, White | G33: Several answers are joined with commas.
A34: Y | B34: Barriers to participation | C34: Does the student currently experience any barriers that may affect participation in educational programs? | E34: Choose several | F34: Transportation
A35: Z | B35: Household income range | C35: Household Annual Income Range | E35: Text | G35: Optional on the form. Sensitive — never copy into other files.
A36: AA | B36: Programs of interest | C36: Which Aspire High programs are you interested in? | E36: Choose several | F36: Free Virtual Tutoring, College & Career Readiness
A37: AB | B37: Student goals | C37: What are the student's primary goals? | E37: Choose several | F37: Improve grades, Prepare for/apply to college
A38: AC | B38: Plan after high school | C38: What does the student plan to do after high school? | E38: Choose one | F38: Four-year college
A39: AD | B39: GPA | C39: Current or Most Recent GPA | E39: Text | F39: 3.2
A40: AE | B40: Academic performance | C40: Current Academic Performance | E40: Text | F40: Mostly Bs
A41: AF | B41: Academic support needed | C41: Which academic areas need additional support? | E41: Choose several | F41: Math, Study Skills
...
